<?xml version="1.0"?>
<robot name="barista_robot">
        
  <material name="red">
    <color rgba="1.0 0.0 0.0 1"/>
  </material>

  <material name="green_light">
    <color rgba="0.0 1.0 0.0 1"/>
  </material>

  <material name="green_dark">
    <color rgba="0.0 0.5 0.0 1"/>
  </material>

  <material name="blue">
    <color rgba="0.0 0.0 1.0 1"/>
  </material>


  <material name="white">
      <color rgba="1.0 1.0 1.0 1"/>
  </material>

	<material name="black">
      <color rgba="0.0 0.0 0.0 1"/>
  </material>

  <link name="base_link">
  </link>

  <!-- Body -->
  <link name="chassis_link">
    <visual>
        <geometry>
            <cylinder radius="0.178" length="0.155"/>
        </geometry>
		<material name="blue"/>
    </visual>

    <collision>
      <geometry>
        <cylinder radius="0.178" length="0.155"/>
      </geometry>
    </collision>

    <inertial>
      <mass value="10"/>
      <inertia ixx="0.099230833" ixy="0" ixz="0" iyy="0.099230833" iyz="0" izz="0.15842"/>
    </inertial>

  </link>

	<gazebo reference="chassis_link">
      <material>Gazebo/Blue</material>
  </gazebo>

  <joint name="base_link_joint" type="fixed">
    <origin rpy="0 0 0" xyz="0 0 0.0775" />
    <parent link="base_link" />
    <child link="chassis_link" />
  </joint>

    <!-- Cup holder tray -->
  <link name="Cup_holder_tray_link">
    <visual>
        <geometry>
            <cylinder radius="0.178" length="0.09"/>
        </geometry>
		<material name="blue"/>
    </visual>

    <collision>
      <geometry>
        <cylinder radius="0.178" length="0.09"/>
      </geometry>
    </collision>

    <inertial>
      <mass value="3"/>
      <inertia ixx="0.025788" ixy="0" ixz="0" iyy="0.025788" iyz="0" izz="0.047526"/>
    </inertial>

  </link>

	<gazebo reference="Cup_holder_tray_link">
      <material>Gazebo/Blue</material>
  </gazebo>

  <joint name="Cup_holder_tray_link_joint" type="fixed">
    <origin rpy="0 0 0" xyz="0 0 0.3425" />
    <parent link="chassis_link" />
    <child link="Cup_holder_tray_link" />
  </joint>

      <!-- standoff rods -->
  <link name="standoff_rod1_link">
    <visual>
        <geometry>
            <cylinder radius="0.01" length="0.22"/>
        </geometry>
		<material name="white"/>
    </visual>

    <collision>
      <geometry>
        <cylinder radius="0.01" length="0.22"/>
      </geometry>
    </collision>

    <inertial>
      <mass value="0.5"/>
      <inertia ixx="0.003266666667" ixy="0" ixz="0" iyy="0.003266666667" iyz="0" izz="0.0025"/>
    </inertial>

  </link>

	<gazebo reference="standoff_rod1_link">
      <material>Gazebo/white</material>
  </gazebo>

  <joint name="standoff_rod1_link_joint" type="fixed">
    <origin rpy="0 0 0" xyz="0.11 0.11 0.1875" />
    <parent link="chassis_link" />
    <child link="standoff_rod1_link" />
  </joint>

    <!-- standoff rods 2 -->
  <link name="standoff_rod2_link">
    <visual>
        <geometry>
            <cylinder radius="0.01" length="0.22"/>
        </geometry>
		<material name="white"/>
    </visual>

    <collision>
      <geometry>
        <cylinder radius="0.01" length="0.22"/>
      </geometry>
    </collision>

    <inertial>
      <mass value="0.5"/>
      <inertia ixx="0.003266666667" ixy="0" ixz="0" iyy="0.003266666667" iyz="0" izz="0.0025"/>
    </inertial>

  </link>

	<gazebo reference="standoff_rod2_link">
      <material>Gazebo/white</material>
  </gazebo>

  <joint name="standoff_rod2_link_joint" type="fixed">
    <origin rpy="0 0 0" xyz="-0.11 0.11 0.1875" />
    <parent link="chassis_link" />
    <child link="standoff_rod2_link" />
  </joint>

        <!-- standoff rods 3 -->
  <link name="standoff_rod3_link">
    <visual>
        <geometry>
            <cylinder radius="0.01" length="0.22"/>
        </geometry>
		<material name="white"/>
    </visual>

    <collision>
      <geometry>
        <cylinder radius="0.01" length="0.22"/>
      </geometry>
    </collision>

    <inertial>
      <mass value="0.5"/>
      <inertia ixx="0.003266666667" ixy="0" ixz="0" iyy="0.003266666667" iyz="0" izz="0.0025"/>
    </inertial>

  </link>

	<gazebo reference="standoff_rod3_link">
      <material>Gazebo/white</material>
  </gazebo>

  <joint name="standoff_rod3_link_joint" type="fixed">
    <origin rpy="0 0 0" xyz="0.11 -0.11 0.1875" />
    <parent link="chassis_link" />
    <child link="standoff_rod3_link" />
  </joint>

        <!-- standoff rods 4 -->
  <link name="standoff_rod4_link">
    <visual>
        <geometry>
            <cylinder radius="0.01" length="0.22"/>
        </geometry>
		<material name="white"/>
    </visual>

    <collision>
      <geometry>
        <cylinder radius="0.01" length="0.22"/>
      </geometry>
    </collision>

    <inertial>
      <mass value="0.5"/>
      <inertia ixx="0.003266666667" ixy="0" ixz="0" iyy="0.003266666667" iyz="0" izz="0.0025"/>
    </inertial>

  </link>

	<gazebo reference="standoff_rod4_link">
      <material>Gazebo/white</material>
  </gazebo>

  <joint name="standoff_rod4_link_joint" type="fixed">
    <origin rpy="0 0 0" xyz="-0.11 -0.11 0.1875" />
    <parent link="chassis_link" />
    <child link="standoff_rod4_link" />
  </joint>

  <!-- Wheel Left -->
  <link name="left_wheel">      
      <visual>
        <origin rpy="0 1.5707 1.5707" xyz="0 0 0"/>
        <geometry>
          <cylinder length="0.0206" radius="0.0352"/>
        </geometry>
        <material name="black"/>
      </visual>

      <collision>
        <origin rpy="0 1.5707 1.5707" xyz="0 0 0"/>
        <geometry>
          <cylinder length="0.0206" radius="0.0352"/>
        </geometry>
      </collision>

      <inertial>
        <origin rpy="0 1.5707 1.5707" xyz="0 0 0"/>
        <mass value="2"/>
        <inertia ixx="0.000690247" ixy="0" ixz="0" iyy="0.000690247" iyz="0" izz="0.00123904"/>
      </inertial>

  </link>

  <gazebo reference="left_wheel">
    <kp>1000000000000000000000000000.0</kp>
    <kd>1000000000000000000000000000.0</kd>
    <mu1>10.0</mu1>
    <mu2>10.0</mu2>
    <material>Gazebo/Black</material>
  </gazebo>


  <joint name="joint_left_wheel" type="continuous">
    <origin rpy="0 0 0" xyz="0 0.15 -0.06"/>
    <child link="left_wheel"/>
    <parent link="chassis_link"/>
    <axis rpy="0 0 0" xyz="0 1 0"/>
    <limit effort="10000" velocity="1000"/>
    <joint_properties damping="1.0" friction="1.0"/>
  </joint>

  <!-- Wheel Right -->
  <link name="right_wheel">      
      <visual>
        <origin rpy="0 1.5707 1.5707" xyz="0 0 0"/>
        <geometry>
          <cylinder length="0.0206" radius="0.0352"/>
        </geometry>
        <material name="black"/>
      </visual>

      <collision>
        <origin rpy="0 1.5707 1.5707" xyz="0 0 0"/>
        <geometry>
          <cylinder length="0.0206" radius="0.0352"/>
        </geometry>
      </collision>

      <inertial>
        <origin rpy="0 1.5707 1.5707" xyz="0 0 0"/>
        <mass value="2"/>
        <inertia ixx="0.000690247" ixy="0" ixz="0" iyy="0.000690247" iyz="0" izz="0.00123904"/>
      </inertial>
  </link>

  <gazebo reference="right_wheel">
    <kp>1000000000000000000000000000.0</kp>
    <kd>1000000000000000000000000000.0</kd>
    <mu1>10.0</mu1>
    <mu2>10.0</mu2>
    <material>Gazebo/Black</material>
  </gazebo>

  <joint name="joint_right_wheel" type="continuous">  
    <origin rpy="0 0 0" xyz="0 -0.15 -0.06"/>
    <child link="right_wheel"/>
    <parent link="chassis_link"/>
    <axis rpy="0 0 0" xyz="0 1 0"/>
    <limit effort="10000" velocity="1000"/>
    <joint_properties damping="1.0" friction="1.0"/>
  </joint>


  <!-- Caster Wheel Front -->
  <link name="front_yaw_link">
      <visual>
        <origin rpy="0 1.5707 1.5707" xyz="0 0 0"/>
        <geometry>          
          <cylinder length="0.01" radius="0.0177"/>
        </geometry>
        <material name="blue"/>
      </visual>

      <collision>
        <origin rpy="0 1.5707 1.5707" xyz="0 0 0"/>
        <geometry>
          <cylinder length="0.01" radius="0.0177"/>
        </geometry>
      </collision>

      <inertial>
          <origin rpy="0 1.5707 1.5707" xyz="0 0 0"/>
          <mass value="0.001"/>
          <inertia ixx="5.145833333333334e-09" ixy="0" ixz="0" iyy="5.145833333333334e-09" iyz="0" izz="1.0125000000000003e-08"/>
      </inertial>

  </link>

  <joint name="front_yaw_joint" type="continuous">
    <origin rpy="0 0 0" xyz="0.15 0 -0.0775" />
    <parent link="chassis_link" />
    <child link="front_yaw_link" />
    <axis xyz="0 0 1" />
    <limit effort="1000.0" velocity="100.0" />
    <dynamics damping="0.0" friction="0.1"/>
  </joint>

    <gazebo reference="front_yaw_link">
        <material>Gazebo/Blue</material>
    </gazebo>


  <link name="front_roll_link">
      <visual>
        <origin rpy="0 1.5707 1.5707" xyz="0 0 0"/>
        <geometry>
          <cylinder length="0.01" radius="0.0177"/>
        </geometry>
        <material name="red"/>
      </visual>

      <collision>
        <origin rpy="0 1.5707 1.5707" xyz="0 0 0"/>
        <geometry>
          <cylinder length="0.01" radius="0.0177"/>
        </geometry>
      </collision>

      <inertial>
          <origin rpy="0 1.5707 1.5707" xyz="0 0 0"/>
          <mass value="0.001"/>
          <inertia ixx="5.145833333333334e-09" ixy="0" ixz="0" iyy="5.145833333333334e-09" iyz="0" izz="1.0125000000000003e-08"/>
      </inertial>
  </link>

  <joint name="front_roll_joint" type="continuous">
    <origin rpy="0 0 0" xyz="0 0 0" />
    <parent link="front_yaw_link" />
    <child link="front_roll_link" />
    <axis xyz="1 0 0" />
    <limit effort="1000.0" velocity="100.0" />
    <dynamics damping="0.0" friction="0.1"/>
  </joint>

    <gazebo reference="front_roll_link">
        <material>Gazebo/Red</material>
    </gazebo>


  <link name="front_pitch_link">
    <visual>
      <origin rpy="0 1.5707 1.5707" xyz="0 0 0"/>
      <geometry>
        <sphere radius="0.0177"/>
      </geometry>
      <material name="green_dark"/>
    </visual>

    <collision>
      <origin rpy="0 1.5707 1.5707" xyz="0 0 0"/>
      <geometry>
        <sphere radius="0.0177"/>
      </geometry>
    </collision>

    <inertial>
        <origin rpy="0 1.5707 1.5707" xyz="0 0 0"/>
        <mass value="0.001"/>
        <inertia ixx="4e-08" ixy="0" ixz="0" iyy="4e-08" iyz="0" izz="4e-08"/>
    </inertial>
  </link>

  <gazebo reference="front_pitch_link">
    <kp>1000000000000000000000000000.0</kp>
    <kd>1000000000000000000000000000.0</kd>
    <mu1>0.5</mu1>
    <mu2>0.5</mu2>
    <material>Gazebo/Purple</material>
  </gazebo>

  <joint name="front_pitch_joint" type="continuous">
    <origin rpy="0 0 0" xyz="0 0 0" />
    <parent link="front_roll_link" />
    <child link="front_pitch_link" />
    <axis xyz="0 1 0" />
    <limit effort="1000.0" velocity="100.0" />
    <dynamics damping="0.0" friction="0.1"/>
  </joint>

<!-- Caster Wheel Back -->
  <link name="back_yaw_link">
    <visual>
        <origin rpy="0 1.5707 1.5707" xyz="0 0 0"/>
        <geometry>
          <cylinder length="0.01" radius="0.0177"/>
        </geometry>
        <material name="blue"/>
      </visual>

      <collision>
        <origin rpy="0 1.5707 1.5707" xyz="0 0 0"/>
        <geometry>
          <cylinder length="0.01" radius="0.0177"/>
        </geometry>
      </collision>

      <inertial>
          <origin rpy="0 1.5707 1.5707" xyz="0 0 0"/>
          <mass value="0.001"/>
          <inertia ixx="5.145833333333334e-09" ixy="0" ixz="0" iyy="5.145833333333334e-09" iyz="0" izz="1.0125000000000003e-08"/>
      </inertial>
  </link>

  <joint name="back_yaw_joint" type="continuous">
    <origin rpy="0 0 0" xyz="-0.15 0 -0.0775" />
    <parent link="chassis_link" />
    <child link="back_yaw_link" />
    <axis xyz="0 0 1" />
    <limit effort="1000.0" velocity="100.0" />
    <dynamics damping="0.0" friction="0.1"/>
  </joint>

    <gazebo reference="back_yaw_link">
        <material>Gazebo/Blue</material>
    </gazebo>



  <link name="back_roll_link">
      <visual>
        <origin rpy="0 1.5707 1.5707" xyz="0 0 0"/>
        <geometry>
          <cylinder length="0.01" radius="0.0177"/>
        </geometry>
        <material name="red"/>
      </visual>

      <collision>
        <origin rpy="0 1.5707 1.5707" xyz="0 0 0"/>
        <geometry>
          <cylinder length="0.01" radius="0.0177"/>
        </geometry>
      </collision>

      <inertial>
          <origin rpy="0 1.5707 1.5707" xyz="0 0 0"/>
          <mass value="0.001"/>
          <inertia ixx="5.145833333333334e-09" ixy="0" ixz="0" iyy="5.145833333333334e-09" iyz="0" izz="1.0125000000000003e-08"/>
      </inertial>
  </link>

  <joint name="back_roll_joint" type="continuous">
    <origin rpy="0 0 0" xyz="0 0 0" />
    <parent link="back_yaw_link" />
    <child link="back_roll_link" />
    <axis xyz="1 0 0" />
    <limit effort="1000.0" velocity="100.0" />
    <dynamics damping="0.0" friction="0.1"/>
  </joint>

    <gazebo reference="back_roll_link">
        <material>Gazebo/Red</material>
    </gazebo>



  <link name="back_pitch_link">
    <visual>
      <origin rpy="0 1.5707 1.5707" xyz="0 0 0"/>
      <geometry>
        <sphere radius="0.0177"/>
      </geometry>
      <material name="green_light"/>
    </visual>

    <collision>
      <origin rpy="0 1.5707 1.5707" xyz="0 0 0"/>
      <geometry>
        <sphere radius="0.0177"/>
      </geometry>
    </collision>

    <inertial>
        <origin rpy="0 1.5707 1.5707" xyz="0 0 0"/>
        <mass value="0.001"/>
        <inertia ixx="4e-08" ixy="0" ixz="0" iyy="4e-08" iyz="0" izz="4e-08"/>
    </inertial>
  </link>

  <gazebo reference="back_pitch_link">
    <kp>1000000000000000000000000000.0</kp>
    <kd>1000000000000000000000000000.0</kd>
    <mu1>0.5</mu1>
    <mu2>0.5</mu2>
    <material>Gazebo/Yellow</material>
  </gazebo>

  <joint name="back_pitch_joint" type="continuous">
    <origin rpy="0 0 0" xyz="0 0 0" />
    <parent link="back_roll_link" />
    <child link="back_pitch_link" />
    <axis xyz="0 1 0" />
    <limit effort="1000.0" velocity="100.0" />
    <dynamics damping="0.0" friction="0.1"/>
  </joint>

  <!-- PLUGINS -->

  <!-- JOINT PUBLISHER -->
  <gazebo>
    <plugin name="barisat_robot_joint_state" filename="libgazebo_ros_joint_state_publisher.so">
      <ros>
          <remapping>~/out:=joint_states</remapping>
      </ros>
      <update_rate>30</update_rate>

      <joint_name>joint_left_wheel</joint_name>
      <joint_name>joint_right_wheel</joint_name>
      <joint_name>front_yaw_joint</joint_name>
      <joint_name>back_yaw_joint</joint_name>
      <joint_name>front_roll_joint</joint_name>
      <joint_name>back_roll_joint</joint_name>
      <joint_name>front_pitch_joint</joint_name>
      <joint_name>back_pitch_joint</joint_name>
      
    </plugin>
  </gazebo>

  <!-- Differential drive -->
  <gazebo>
    <plugin filename="libgazebo_ros_diff_drive.so" name="differential_drive_controller">

      <!-- wheels -->
      <left_joint>joint_left_wheel</left_joint>
      <right_joint>joint_right_wheel</right_joint>

      <!-- kinematics -->
      <wheel_separation>0.3</wheel_separation>
      <wheel_diameter>0.0704</wheel_diameter>

      <!-- limits -->
      <max_wheel_torque>1.0</max_wheel_torque>
      <max_wheel_acceleration>2.0</max_wheel_acceleration>

      <!-- output -->
      <publish_odom>true</publish_odom>
      <publish_odom_tf>true</publish_odom_tf>

      <odometry_frame>odom</odometry_frame>
      <robot_base_frame>base_link</robot_base_frame>

    </plugin>
  </gazebo>

  <!-- Sensors -->
<!-- Visual Laser Model to be rotated -->
  <link name="laser_scan_model_link">
    <visual>
      <origin rpy="0 0 0" xyz="0 0 0"/>
      <geometry>
        <mesh filename="package://barista_robot_description/meshes/sensors/hokuyo_urg_04lx.dae" scale="1.0 1.0 1.0"/>
      </geometry>
    </visual>

    <collision>
       <origin rpy="0 0 0" xyz="0 0 0.0204"/>
      <geometry>
        <cylinder length="0.0408" radius="0.037493"/>
      </geometry>
    </collision>

    <inertial>

      <mass value="0.01"/>
      <origin rpy="0 0 0" xyz="0 0 0.0204"/>
      <inertia ixx="6.066578520833334e-06" ixy="0" ixz="0" iyy="6.072950163333333e-06" iyz="0" izz="9.365128684166666e-06"/>
    </inertial>
  </link>

  <joint name="laser_scan_model_link_joint" type="continuous">
    <origin rpy="0 0 0" xyz="0.1 0.0 0.0775"/>
    <parent link="chassis_link"/>
    <child link="laser_scan_model_link"/>
    <axis xyz="0 0 1"/>
    <limit effort="10.0" velocity="2.0"/>
    <dynamics friction="0.01"/>
  </joint>


  <gazebo reference="laser_scan_frame">
    <sensor name="sensor_ray" type="ray">
        <pose>0 0 0 0 0 0</pose>
        <ray>
          <scan>
            <horizontal>
              <samples>200</samples>
              <resolution>1.0</resolution>
              <min_angle>-3.14</min_angle>
              <max_angle>3.14</max_angle>
            </horizontal>
          </scan>
          <range>
            <min>0.1</min>
            <max>5.0</max>
          </range>
        </ray>
        <always_on>true</always_on>
        <visualize>true</visualize>
        <update_rate>100.0</update_rate>
        <plugin name="laser" filename="libgazebo_ros_ray_sensor.so">
          <ros>
            <namespace>/barista_robot</namespace>
            <remapping>~/out:=laser_scan</remapping>
          </ros>
          <output_type>sensor_msgs/LaserScan</output_type>
        </plugin>
    </sensor>
  </gazebo>




</robot>